---
layout: post
title : ES6-Promise学习笔记
description: 
categories: code
author: Tim Gao
tags: [codes]
---

# 1. Promise的含义

Promise 是异步编程的一种解决方案。从语法上讲，promise是一个对象，可以获取异步操作的消息。它提供了统一的API，各种异步操作都可以以同样的方式处理。Promise对象有三种状态pending(进行中),fullfilled(已成功),rejected（已失败）。

Promise对象的2个特点

* (1) 对象的状态不受外界的影响.只有异步操作的结果可以决定当前是哪一种状态,任何其他操作都无法改变这种状态。
* (2) 一旦状态改变就永远不会变化，任何时候都可以得到这个结果。

Promise的状态改变只能有两种情况: 从pending到fullfilled或者从pending到rejected.
有了Promise对象，就可以将异步操作以同步操作的流程表达出来，避免了层层嵌套的回调函数。此外，Promise对象提供统一的接口，使得控制异步操作更加容易

Promise的3个缺点

* (1) 无法取消Promise，一旦新建它就会立即执行，无法中途取消。

* (2) 如果不设置回调函数，Promise内部抛出的错误，不会反应到外部。

* (3) 当处于pending状态时，无法得知目前进展到哪一个阶段（刚刚开始还是即将完成）。

# 2. 基本用法

    const promise = new Promise(function(resolve, reject) {
        // ... some code

        if (/* 异步操作成功 */){
            resolve(value);
        } else {
            reject(error);
        }
    });

Promise构造函数接受一个函数作为参数，该函数的两个参数分别是resolve和reject。它们是两个函数，由 JavaScript 引擎提供，不用自己部署。

resolve函数的作用是，将Promise对象的状态从“未完成”变为“成功”（即从 pending 变为 resolved），在异步操作成功时调用，并将异步操作的结果，作为参数传递出去；
reject函数的作用是，将Promise对象的状态从“未完成”变为“失败”（即从 pending 变为 rejected），在异步操作失败时调用，并将异步操作报出的错误，作为参数传递出去。

Promise实例生成之后，可以用**then**方法指定成功和失败的回调

    promise.then(function(value) {
    // success
    }, function(error) {
    // failure
    });

then方法可以接受两个回调函数作为参数。第一个回调函数是Promise对象的状态变为resolved时调用，第二个回调函数是Promise对象的状态变为rejected时调用。其中，第二个函数是可选的，不一定要提供。这两个函数都接受Promise对象传出的值作为参数。

    function timeout(ms) {
    return new Promise((resolve, reject) => {
        setTimeout(resolve, ms, 'done');
    });
    }

    timeout(100).then((value) => {
    console.log(value);
    });
    //100毫秒后输出'done'

Promise 新建后就会立即执行。

    let promise = new Promise(function(resolve, reject) {
    console.log('Promise');
    resolve();
    });

    promise.then(function() {
    console.log('resolved.');
    });

    console.log('Hi!');

    // Promise
    // Hi!
    // resolved

# 3. Promise.prototype.then

then的作用是为 Promise 实例添加状态改变时的回调函数。then方法的第一个参数是resolved状态的回调函数，第二个参数（可选）是rejected状态的回调函数。

then返回的还是一个Promise对象，因此可以采用链式写法

    getJSON("/posts.json").then(function(json) {
        return json.post;
    }).then(function(post) {
        // ...
    });

# 4. Promise.prototype.catch

Promise.prototype.catch方法是.then(null, rejection)的别名，用于指定发生错误时的回调函数。

    getJSON('/posts.json').then(function(posts) {
        // ...
    }).catch(function(error) {
        // 处理 getJSON 和 前一个回调函数运行时发生的错误
        console.log('发生错误！', error);
    });

如果 Promise 状态已经变成resolved，再抛出错误是无效的。

    const promise = new Promise(function(resolve, reject) {
        resolve('ok');
        throw new Error('test');
    });
    promise
    .then(function(value) { console.log(value) })
    .catch(function(error) { console.log(error) });
    // ok

Promise 对象的错误具有“冒泡”性质，会一直向后传递，直到被捕获为止。也就是说，错误总是会被下一个catch语句捕获。

    getJSON('/post/1.json').then(function(post) {
        return getJSON(post.commentURL);
    }).then(function(comments) {
        // some code
    }).catch(function(error) {
        // 处理前面三个Promise产生的错误
    });

一般来说，不要在then方法里面定义 Reject 状态的回调函数（即then的第二个参数），总是使用catch方法。

    // bad
    promise
    .then(function(data) {
        // success
    }, function(err) {
        // error
    });

    // good
    promise
    .then(function(data) { //cb
        // success
    })
    .catch(function(err) {
        // error
    });

# 5. Promise.prototype.finally

finally方法用于指定不管 Promise 对象最后状态如何，都会执行的操作。该方法是 ES2018 引入标准的。

    promise
    .then(result => {···})
    .catch(error => {···})
    .finally(() => {···});

finally方法的回调函数不接受任何参数，这意味着没有办法知道，前面的 Promise 状态到底是fulfilled还是rejected。这表明，finally方法里面的操作，应该是与状态无关的，不依赖于 Promise 的执行结果。

# 6. Promise.all

Promise.all方法用于将多个Promise实例，包装成一个新的Promise实例。

    const p = Promise.all([p1, p2, p3]);

Promise.all方法接受一个数组作为参数，其中p1,p2,p3都是Promise实例, 如果不是，就会调用下面讲到的`Promise.resolve`将其转换为Promise实例再处理。

上面p的状态由p1, p2, p3决定，具体分为两种情况

(1) 只有p1、p2、p3的状态都变成fulfilled，p的状态才会变成fulfilled，此时p1、p2、p3的返回值组成一个数组，传递给p的回调函数。

(2）只要p1、p2、p3之中有一个被rejected，p的状态就变成rejected，此时第一个被reject的实例的返回值，会传递给p的回调函数。

下面是具体例子：

    const promises = [1,2,3,4,5,6].map(function(id){
        return getJSON('/post/'+id+'.json')
    })
    Promise.all(promises)
    .then(function(posts){
        //...
    })
    .catch(function(reason){
        //...
    })

上面代码中，promises是包含 6 个 Promise 实例的数组，只有这 6 个实例的状态都变成fulfilled，或者其中有一个变为rejected，才会调用Promise.all方法后面的回调函数

注意，如果作为参数的 Promise 实例，自己定义了catch方法，那么它一旦被rejected，并不会触发Promise.all()的catch方法。

# 7. Promise.race

Promise.race同样是将多个promise实例,包装成一个新的Promise实例

    const p = Promise.race([p1, p2, p3]);

上面代码中，只要p1、p2、p3之中有一个实例率先改变状态，p的状态就跟着改变。那个率先改变的 Promise 实例的返回值，就传递给p的回调函数。

    const p = Promise.race([
        fetch('/resource-that-may-take-a-while'),
        new Promise(function(resolve, reject){
            setTimout(()=> reject(new Error('request timeout')),5000)
        })
    ]).then(function(){

    }).catch(function(){
        
    })

上面实例如果在5秒内第一个请求没有返回, p就会变成rejected, 从而触发catch方法指定的回调函数

# 8. Promise.resolve

Promise.resove方法可以将现有对象转换为Promise对象

    const jsPromise = Promise.resolve($.ajax('/whatever.json'));

Promise.resolve等价于下面的写法

    Promise.resolve('foo')
    //等价于
    new Promise(resolve => resolve('foo'))

Promise.resolve方法的参数分为四种情况。

__(1) 参数是一个Promise实例__

如果参数是 Promise 实例，那么Promise.resolve将不做任何修改、原封不动地返回这个实例。

__(2) 参数是一个thenable对象__

thenable对象指的是具有then方法的对象，

    let thenable = {
        then: function(resolve, reject) {
            resolve(42);
        }
    }

Promise.resolve方法会将这个对象转为 Promise 对象，然后就立即执行thenable对象的then方法。

__(3) 参数不是具有then方法的对象,或者根本就不是对象__

如果参数是一个原始值，或者是一个不具有then方法的对象，则Promise.resolve方法返回一个新的 Promise 对象，状态为resolved。

__(4) 不带任何参数__

Promise.resolve方法允许调用时不带参数，直接返回一个resolved状态的 Promise 对象。

    setTimeout(function () {
        console.log('three');
    }, 0);

    Promise.resolve().then(function () {
        console.log('two');
    });

    console.log('one');

    // one
    // two
    // three

上面代码中，setTimeout(fn, 0)在下一轮“事件循环”开始时执行，Promise.resolve()在本轮“事件循环”结束时执行，console.log('one')则是立即执行，因此最先输出。

# 9. Promise.reject

Promise.reject(reason)方法也会返回一个新的 Promise 实例，该实例的状态为rejected。

注意，Promise.reject()方法的参数，会原封不动地作为reject的理由，变成后续方法的参数。这一点与Promise.resolve方法不一致。

    const thenable = {
        then(resolve, reject) {
            reject('出错了');
        }
    };

    Promise.reject(thenable)
    .catch(e => {
        console.log(e === thenable)
    })
    // true

上面代码中，Promise.reject方法的参数是一个thenable对象，执行以后，后面catch方法的参数不是reject抛出的“出错了”这个字符串，而是thenable对象。